/home/joberant/NLP_2425a/sharonsaban/anaconda3/envs/sharon_env/lib/python3.10/site-packages/huggingface_hub/file_download.py:896: FutureWarning: `resume_download` is deprecated and will be removed in version 1.0.0. Downloads always resume when possible. If you want to force a new download, use `force_download=True`.
  warnings.warn(
Traceback (most recent call last):
  File "/home/joberant/NLP_2425a/sharonsaban/anaconda3/envs/sharon_env/lib/python3.10/site-packages/huggingface_hub/utils/_http.py", line 409, in hf_raise_for_status
    response.raise_for_status()
  File "/home/joberant/NLP_2425a/sharonsaban/anaconda3/envs/sharon_env/lib/python3.10/site-packages/requests/models.py", line 1024, in raise_for_status
    raise HTTPError(http_error_msg, response=self)
requests.exceptions.HTTPError: 404 Client Error: Not Found for url: https://huggingface.co/meta-llama/Llama-3-70b/resolve/main/config.json

The above exception was the direct cause of the following exception:

Traceback (most recent call last):
  File "/home/joberant/NLP_2425a/sharonsaban/anaconda3/envs/sharon_env/lib/python3.10/site-packages/transformers/utils/hub.py", line 417, in cached_file
    resolved_file = hf_hub_download(
  File "/home/joberant/NLP_2425a/sharonsaban/anaconda3/envs/sharon_env/lib/python3.10/site-packages/huggingface_hub/utils/_validators.py", line 114, in _inner_fn
    return fn(*args, **kwargs)
  File "/home/joberant/NLP_2425a/sharonsaban/anaconda3/envs/sharon_env/lib/python3.10/site-packages/huggingface_hub/file_download.py", line 961, in hf_hub_download
    return _hf_hub_download_to_cache_dir(
  File "/home/joberant/NLP_2425a/sharonsaban/anaconda3/envs/sharon_env/lib/python3.10/site-packages/huggingface_hub/file_download.py", line 1068, in _hf_hub_download_to_cache_dir
    _raise_on_head_call_error(head_call_error, force_download, local_files_only)
  File "/home/joberant/NLP_2425a/sharonsaban/anaconda3/envs/sharon_env/lib/python3.10/site-packages/huggingface_hub/file_download.py", line 1596, in _raise_on_head_call_error
    raise head_call_error
  File "/home/joberant/NLP_2425a/sharonsaban/anaconda3/envs/sharon_env/lib/python3.10/site-packages/huggingface_hub/file_download.py", line 1484, in _get_metadata_or_catch_error
    metadata = get_hf_file_metadata(
  File "/home/joberant/NLP_2425a/sharonsaban/anaconda3/envs/sharon_env/lib/python3.10/site-packages/huggingface_hub/utils/_validators.py", line 114, in _inner_fn
    return fn(*args, **kwargs)
  File "/home/joberant/NLP_2425a/sharonsaban/anaconda3/envs/sharon_env/lib/python3.10/site-packages/huggingface_hub/file_download.py", line 1401, in get_hf_file_metadata
    r = _request_wrapper(
  File "/home/joberant/NLP_2425a/sharonsaban/anaconda3/envs/sharon_env/lib/python3.10/site-packages/huggingface_hub/file_download.py", line 285, in _request_wrapper
    response = _request_wrapper(
  File "/home/joberant/NLP_2425a/sharonsaban/anaconda3/envs/sharon_env/lib/python3.10/site-packages/huggingface_hub/file_download.py", line 309, in _request_wrapper
    hf_raise_for_status(response)
  File "/home/joberant/NLP_2425a/sharonsaban/anaconda3/envs/sharon_env/lib/python3.10/site-packages/huggingface_hub/utils/_http.py", line 459, in hf_raise_for_status
    raise _format(RepositoryNotFoundError, message, response) from e
huggingface_hub.errors.RepositoryNotFoundError: 404 Client Error. (Request ID: Root=1-680cc7a3-618201f127a4a01c1cefa5fb;44c0a8ff-7ba0-475c-8dba-037286f2bd81)

Repository Not Found for url: https://huggingface.co/meta-llama/Llama-3-70b/resolve/main/config.json.
Please make sure you specified the correct `repo_id` and `repo_type`.
If you are trying to access a private or gated repo, make sure you are authenticated. For more details, see https://huggingface.co/docs/huggingface_hub/authentication

During handling of the above exception, another exception occurred:

Traceback (most recent call last):
  File "/vol/joberant_nobck/data/NLP_368307701_2425a/sharonsaban/NLP_FINAL_PROJECT/run_all_models.py", line 72, in <module>
    main(model_name)
  File "/vol/joberant_nobck/data/NLP_368307701_2425a/sharonsaban/NLP_FINAL_PROJECT/run_all_models.py", line 55, in main
    model = AutoModelForCausalLM.from_pretrained(model_name, device_map="auto")
  File "/home/joberant/NLP_2425a/sharonsaban/anaconda3/envs/sharon_env/lib/python3.10/site-packages/transformers/models/auto/auto_factory.py", line 456, in from_pretrained
    config, kwargs = AutoConfig.from_pretrained(
  File "/home/joberant/NLP_2425a/sharonsaban/anaconda3/envs/sharon_env/lib/python3.10/site-packages/transformers/models/auto/configuration_auto.py", line 944, in from_pretrained
    config_dict, unused_kwargs = PretrainedConfig.get_config_dict(pretrained_model_name_or_path, **kwargs)
  File "/home/joberant/NLP_2425a/sharonsaban/anaconda3/envs/sharon_env/lib/python3.10/site-packages/transformers/configuration_utils.py", line 574, in get_config_dict
    config_dict, kwargs = cls._get_config_dict(pretrained_model_name_or_path, **kwargs)
  File "/home/joberant/NLP_2425a/sharonsaban/anaconda3/envs/sharon_env/lib/python3.10/site-packages/transformers/configuration_utils.py", line 629, in _get_config_dict
    resolved_config_file = cached_file(
  File "/home/joberant/NLP_2425a/sharonsaban/anaconda3/envs/sharon_env/lib/python3.10/site-packages/transformers/utils/hub.py", line 433, in cached_file
    raise EnvironmentError(
OSError: meta-llama/Llama-3-70b is not a local folder and is not a valid model identifier listed on 'https://huggingface.co/models'
If this is a private repository, make sure to pass a token having permission to this repo with `use_auth_token` or log in with `huggingface-cli login` and pass `use_auth_token=True`.
slurmstepd: error: _cgroup_procs_check: failed on path (null)/cgroup.procs: No such file or directory
slurmstepd: error: Cannot write to cgroup.procs for (null)
slurmstepd: error: Unable to move pid 1094605 to init root cgroup (null)
